{
  "fileName": "catch-error.js",
  "filePath": "src/diff/catch-error.js",
  "url": "https://github.com/preactjs/preact/src/diff/catch-error.js",
  "summary": "The code provided is a function called `_catchError` that is used to find the closest error boundary to a thrown error and call it. \n\nThe function takes four parameters:\n- `error`: The thrown value, which represents the error that was thrown.\n- `vnode`: The vnode (virtual node) that threw the error. This parameter is used to track the hierarchy of vnodes and find the closest error boundary.\n- `oldVNode`: An optional parameter that represents the previous vnode. It is not used in the code provided.\n- `errorInfo`: An optional parameter that represents additional information about the error. It is not used in the code provided.\n\nThe function starts by declaring three variables: `component`, `ctor`, and `handled`. These variables will be used to track the component, its constructor, and whether the error has been handled.\n\nThe function then enters a loop that iterates through the parent vnodes of the current vnode. This loop allows the function to traverse up the vnode hierarchy and find the closest error boundary.\n\nInside the loop, the function checks if the current vnode has a component and if it has not already processed an exception. If these conditions are met, the function tries to handle the error by calling `getDerivedStateFromError` and `componentDidCatch` methods on the component.\n\nIf the component has a `getDerivedStateFromError` method, the function calls it with the `error` parameter and sets the state of the component with the returned value. The `handled` variable is then set to `true` if the component's state has been updated.\n\nIf the component has a `componentDidCatch` method, the function calls it with the `error` and `errorInfo` parameters. The `handled` variable is again set to `true` if the component's state has been updated.\n\nAfter handling the error, the function checks if the error has been handled. If it has, the function sets the `_pendingError` property of the component to itself and returns the component.\n\nIf an error occurs while handling the error, the function catches the error and assigns it to the `error` variable. This allows the function to continue searching for an error boundary in the vnode hierarchy.\n\nIf no error boundary is found in the vnode hierarchy, the function throws the original error.\n\nIn the larger project, this function is likely used as part of the error handling mechanism in the Preact library. When an error occurs during rendering or updating of components, this function is called to find the closest error boundary and handle the error appropriately. This helps prevent the entire application from crashing and allows for graceful error handling and recovery.",
  "questions": "1. What is the purpose of this function?\n- This function is used to find the closest error boundary to a thrown error and call it.\n\n2. What are the parameters of this function?\n- The parameters of this function are `error` (the thrown value), `vnode` (the vnode that threw the error), `oldVNode` (optional parameter), and `errorInfo` (optional parameter).\n\n3. What does the function do if it finds an error boundary?\n- If the function finds an error boundary, it calls the `getDerivedStateFromError` method of the component's constructor (if available) and sets the state of the component with the returned value. It also calls the `componentDidCatch` method of the component (if available) and marks the component as having handled the error."
}